Workbook

Sheet Doc_truoc_khi_dung
A1: Mục | B1: Nội dung
A2: Mục đích | B2: Ngân hàng câu hỏi Lớp 1 gồm 120 câu (40 câu/môn; 8 câu/cấp độ/môn): 45 câu bộ mẫu ban đầu + 75 câu soạn thêm. Kèm 713 câu bài tập theo sách (Học kì 1; riêng Toán có cả Học kì 2, Bài 21–41) ở sheet Bai_tap_theo_sach.
A3: Căn cứ chính | B3: Chương trình GDPT ban hành kèm Thông tư 32/2018/TT-BGDĐT và văn bản sửa đổi còn hiệu lực; cần kiểm tra văn bản chính thức hiện hành trước khi xuất bản.
A4: Nguồn chương trình tổng thể | B4: https://moet.gov.vn/content/tintuc/Lists/News/Attachments/8421/chuong-trinh-tong-the-ctgdpt-2018.pdf
A5: Nguồn thông tin sửa đổi | B5: https://www.moet.gov.vn/tintuc/Pages/CT-GDPT-Tong-The.aspx/casino%20Matchbook%20Custom?ItemID=8013
A6: Phân biệt chính thức và đề xuất | B6: Chương trình chính thức quy định yêu cầu cần đạt; L1–L5 là thang phân tầng nội bộ EduChain Kids, không phải cấp độ chính thức của Bộ.
A7: L1 | B7: Nhận biết trực tiếp, thao tác đơn giản.
A8: L2 | B8: Hiểu và thực hiện dạng quen thuộc đã học.
A9: L3 | B9: Vận dụng kiến thức đã học vào tình huống quen thuộc.
A10: L4 | B10: Kết hợp vài kỹ năng đã học; không vượt chuẩn.
A11: L5 | B11: Mở rộng tư duy trên kiến thức đã học; không dạy trước kiến thức lớp trên.
A12: Tiến trình | B12: Không gán tuần/tháng cứng vì tiến độ tùy kế hoạch giáo dục, SGK và học sinh. Giáo viên chọn giai đoạn thực tế.
... A26: Sửa nội dung | B26: Nguồn chính là file src/lib/content/ngan-hang-lop1.ts trong dự án. Sửa ở đó rồi chạy npm run check:content, npm run gen:sql và npm run export:bank để tạo lại file này.

Sheet Khung_cap_do
A1: Cấp độ nội bộ | B1: Mô tả | C1: Dấu hiệu | D1: Điều kiện bắt buộc | E1: Không được làm | F1: Mức quen thuộc | G1: Thời gian gốc (giây) | H1: Điểm khi đúng
A2: L1 — Làm quen | B2: Nhận biết, chỉ ra, ghép trực tiếp | C2: Chọn số/chữ/từ đã học | D2: Kiến thức đã dạy; hình rõ | E2: Không hỏi nội dung chưa học | F2: Nhận biết | G2: 30 | H2: 10
A3: L2 — Cơ bản | B3: Thực hiện dạng quen thuộc | C3: Tính toán/hiểu nghĩa trực tiếp | D3: Không cần chiến lược mới | E3: Không làm khó bằng câu chữ rối | F3: Thông hiểu | G3: 40 | H3: 15
A4: L3 — Vận dụng | B4: Áp dụng trong ngữ cảnh quen thuộc | C4: Bài toán thêm/bớt; hiểu câu ngắn | D4: Đủ kiến thức nền | E4: Không dùng từ ngoài vốn từ | F4: Vận dụng | G4: 50 | H4: 20
A5: L4 — Thử thách | B5: Kết hợp vài kỹ năng đã học | C5: Chọn phép tính; đọc câu liên kết | D5: Giáo viên xác nhận phạm vi | E5: Không đồng nghĩa kiến thức lớp trên | F5: — | G5: 60 | H5: 25
A6: L5 — Mở rộng | B6: Tình huống mới, giải thích hoặc nhiều đáp án | C6: Tách số; câu trả lời mở | D6: Có rubric và dùng kiến thức đã học | E6: Không gắn nhãn chuẩn Bộ | F6: — | G6: 75 | H6: 30
A8: Thời gian cộng thêm theo dạng câu
A9: Chọn đáp án, Đúng/Sai | B9: 0
A10: Điền đáp án, Chọn nhiều | B10: 10
A11: Sắp xếp, Ghép cặp | B11: 15
A12: Đề dài hơn 60 ký tự | B12: 10
A13: Giới hạn | B13: 30–120 giây
A15: Chữ xanh: số có thể chỉnh. Cột Điểm khi đúng ở các sheet câu hỏi lấy từ cột H ở đây. Thời gian từng câu trong các sheet câu hỏi là giá trị đã tính (giáo viên sửa được từng câu); đổi quy tắc thời gian thì sửa src/lib/levels.ts và migration 0006 rồi xuất lại file.

Sheet Tong_hop
A1: Môn học | B1: Cấp độ | C1: Tên cấp độ | D1: Số câu ngân hàng | E1: Câu bộ mẫu | F1: Câu soạn thêm | G1: Có lời giải chi tiết | H1: Thời gian TB (giây) | I1: Điểm khi đúng | J1: Câu bài tập theo sách
A2: Toán | B2: 1 | C2: Làm quen | D2: =COUNTIFS(Ngan_hang_cau_hoi!$B:$B,$A2,Ngan_hang_cau_hoi!$F:$F,$B2) | E2: =COUNTIFS(Ngan_hang_cau_hoi!$B:$B,$A2,Ngan_hang_cau_hoi!$F:$F,$B2,Ngan_hang_cau_hoi!$Z:$Z,"Bộ mẫu") | F2: =COUNTIFS(Ngan_hang_cau_hoi!$B:$B,$A2,Ngan_hang_cau_hoi!$F:$F,$B2,Ngan_hang_cau_hoi!$Z:$Z,"Soạn thêm") | G2: =COUNTIFS(Ngan_hang_cau_hoi!$B:$B,$A2,Ngan_hang_cau_hoi!$F:$F,$B2,Ngan_hang_cau_hoi!$S:$S,"<>") | H2: =IFERROR(ROUND(AVERAGEIFS(Ngan_hang_cau_hoi!$T:$T,Ngan_hang_cau_hoi!$B:$B,$A2,Ngan_hang_cau_hoi!$F:$F,$B2),0),0) | I2: =INDEX(Khung_cap_do!$H$2:$H$6,$B2) | J2: =COUNTIFS(Bai_tap_theo_sach!$B:$B,$A2,Bai_tap_theo_sach!$H:$H,$B2)
A3: Toán | B3: 2 | C3: Cơ bản | D3: =COUNTIFS(Ngan_hang_cau_hoi!$B:$B,$A3,Ngan_hang_cau_hoi!$F:$F,$B3) | E3: =COUNTIFS(Ngan_hang_cau_hoi!$B:$B,$A3,Ngan_hang_cau_hoi!$F:$F,$B3,Ngan_hang_cau_hoi!$Z:$Z,"Bộ mẫu") | F3: =COUNTIFS(Ngan_hang_cau_hoi!$B:$B,$A3,Ngan_hang_cau_hoi!$F:$F,$B3,Ngan_hang_cau_hoi!$Z:$Z,"Soạn thêm") | G3: =COUNTIFS(Ngan_hang_cau_hoi!$B:$B,$A3,Ngan_hang_cau_hoi!$F:$F,$B3,Ngan_hang_cau_hoi!$S:$S,"<>") | H3: =IFERROR(ROUND(AVERAGEIFS(Ngan_hang_cau_hoi!$T:$T,Ngan_hang_cau_hoi!$B:$B,$A3,Ngan_hang_cau_hoi!$F:$F,$B3),0),0) | I3: =INDEX(Khung_cap_do!$H$2:$H$6,$B3) | J3: =COUNTIFS(Bai_tap_theo_sach!$B:$B,$A3,Bai_tap_theo_sach!$H:$H,$B3)
A4: Toán | B4: 3 | C4: Vận dụng | D4: =COUNTIFS(Ngan_hang_cau_hoi!$B:$B,$A4,Ngan_hang_cau_hoi!$F:$F,$B4) | E4: =COUNTIFS(Ngan_hang_cau_hoi!$B:$B,$A4,Ngan_hang_cau_hoi!$F:$F,$B4,Ngan_hang_cau_hoi!$Z:$Z,"Bộ mẫu") | F4: =COUNTIFS(Ngan_hang_cau_hoi!$B:$B,$A4,Ngan_hang_cau_hoi!$F:$F,$B4,Ngan_hang_cau_hoi!$Z:$Z,"Soạn thêm") | G4: =COUNTIFS(Ngan_hang_cau_hoi!$B:$B,$A4,Ngan_hang_cau_hoi!$F:$F,$B4,Ngan_hang_cau_hoi!$S:$S,"<>") | H4: =IFERROR(ROUND(AVERAGEIFS(Ngan_hang_cau_hoi!$T:$T,Ngan_hang_cau_hoi!$B:$B,$A4,Ngan_hang_cau_hoi!$F:$F,$B4),0),0) | I4: =INDEX(Khung_cap_do!$H$2:$H$6,$B4) | J4: =COUNTIFS(Bai_tap_theo_sach!$B:$B,$A4,Bai_tap_theo_sach!$H:$H,$B4)
A5: Toán | B5: 4 | C5: Thử thách | D5: =COUNTIFS(Ngan_hang_cau_hoi!$B:$B,$A5,Ngan_hang_cau_hoi!$F:$F,$B5) | E5: =COUNTIFS(Ngan_hang_cau_hoi!$B:$B,$A5,Ngan_hang_cau_hoi!$F:$F,$B5,Ngan_hang_cau_hoi!$Z:$Z,"Bộ mẫu") | F5: =COUNTIFS(Ngan_hang_cau_hoi!$B:$B,$A5,Ngan_hang_cau_hoi!$F:$F,$B5,Ngan_hang_cau_hoi!$Z:$Z,"Soạn thêm") | G5: =COUNTIFS(Ngan_hang_cau_hoi!$B:$B,$A5,Ngan_hang_cau_hoi!$F:$F,$B5,Ngan_hang_cau_hoi!$S:$S,"<>") | H5: =IFERROR(ROUND(AVERAGEIFS(Ngan_hang_cau_hoi!$T:$T,Ngan_hang_cau_hoi!$B:$B,$A5,Ngan_hang_cau_hoi!$F:$F,$B5),0),0) | I5: =INDEX(Khung_cap_do!$H$2:$H$6,$B5) | J5: =COUNTIFS(Bai_tap_theo_sach!$B:$B,$A5,Bai_tap_theo_sach!$H:$H,$B5)
A6: Toán | B6: 5 | C6: Mở rộng | D6: =COUNTIFS(Ngan_hang_cau_hoi!$B:$B,$A6,Ngan_hang_cau_hoi!$F:$F,$B6) | E6: =COUNTIFS(Ngan_hang_cau_hoi!$B:$B,$A6,Ngan_hang_cau_hoi!$F:$F,$B6,Ngan_hang_cau_hoi!$Z:$Z,"Bộ mẫu") | F6: =COUNTIFS(Ngan_hang_cau_hoi!$B:$B,$A6,Ngan_hang_cau_hoi!$F:$F,$B6,Ngan_hang_cau_hoi!$Z:$Z,"Soạn thêm") | G6: =COUNTIFS(Ngan_hang_cau_hoi!$B:$B,$A6,Ngan_hang_cau_hoi!$F:$F,$B6,Ngan_hang_cau_hoi!$S:$S,"<>") | H6: =IFERROR(ROUND(AVERAGEIFS(Ngan_hang_cau_hoi!$T:$T,Ngan_hang_cau_hoi!$B:$B,$A6,Ngan_hang_cau_hoi!$F:$F,$B6),0),0) | I6: =INDEX(Khung_cap_do!$H$2:$H$6,$B6) | J6: =COUNTIFS(Bai_tap_theo_sach!$B:$B,$A6,Bai_tap_theo_sach!$H:$H,$B6)
A7: Cộng Toán | D7: =SUM(D2:D6) | E7: =SUM(E2:E6) | F7: =SUM(F2:F6) | G7: =SUM(G2:G6) | H7: =IFERROR(ROUND(AVERAGEIFS(Ngan_hang_cau_hoi!$T:$T,Ngan_hang_cau_hoi!$B:$B,"Toán"),0),0) | J7: =SUM(J2:J6)
A8: Tiếng Việt | B8: 1 | C8: Làm quen | D8: =COUNTIFS(Ngan_hang_cau_hoi!$B:$B,$A8,Ngan_hang_cau_hoi!$F:$F,$B8) | E8: =COUNTIFS(Ngan_hang_cau_hoi!$B:$B,$A8,Ngan_hang_cau_hoi!$F:$F,$B8,Ngan_hang_cau_hoi!$Z:$Z,"Bộ mẫu") | F8: =COUNTIFS(Ngan_hang_cau_hoi!$B:$B,$A8,Ngan_hang_cau_hoi!$F:$F,$B8,Ngan_hang_cau_hoi!$Z:$Z,"Soạn thêm") | G8: =COUNTIFS(Ngan_hang_cau_hoi!$B:$B,$A8,Ngan_hang_cau_hoi!$F:$F,$B8,Ngan_hang_cau_hoi!$S:$S,"<>") | H8: =IFERROR(ROUND(AVERAGEIFS(Ngan_hang_cau_hoi!$T:$T,Ngan_hang_cau_hoi!$B:$B,$A8,Ngan_hang_cau_hoi!$F:$F,$B8),0),0) | I8: =INDEX(Khung_cap_do!$H$2:$H$6,$B8) | J8: =COUNTIFS(Bai_tap_theo_sach!$B:$B,$A8,Bai_tap_theo_sach!$H:$H,$B8)
A9: Tiếng Việt | B9: 2 | C9: Cơ bản | D9: =COUNTIFS(Ngan_hang_cau_hoi!$B:$B,$A9,Ngan_hang_cau_hoi!$F:$F,$B9) | E9: =COUNTIFS(Ngan_hang_cau_hoi!$B:$B,$A9,Ngan_hang_cau_hoi!$F:$F,$B9,Ngan_hang_cau_hoi!$Z:$Z,"Bộ mẫu") | F9: =COUNTIFS(Ngan_hang_cau_hoi!$B:$B,$A9,Ngan_hang_cau_hoi!$F:$F,$B9,Ngan_hang_cau_hoi!$Z:$Z,"Soạn thêm") | G9: =COUNTIFS(Ngan_hang_cau_hoi!$B:$B,$A9,Ngan_hang_cau_hoi!$F:$F,$B9,Ngan_hang_cau_hoi!$S:$S,"<>") | H9: =IFERROR(ROUND(AVERAGEIFS(Ngan_hang_cau_hoi!$T:$T,Ngan_hang_cau_hoi!$B:$B,$A9,Ngan_hang_cau_hoi!$F:$F,$B9),0),0) | I9: =INDEX(Khung_cap_do!$H$2:$H$6,$B9) | J9: =COUNTIFS(Bai_tap_theo_sach!$B:$B,$A9,Bai_tap_theo_sach!$H:$H,$B9)
A10: Tiếng Việt | B10: 3 | C10: Vận dụng | D10: =COUNTIFS(Ngan_hang_cau_hoi!$B:$B,$A10,Ngan_hang_cau_hoi!$F:$F,$B10) | E10: =COUNTIFS(Ngan_hang_cau_hoi!$B:$B,$A10,Ngan_hang_cau_hoi!$F:$F,$B10,Ngan_hang_cau_hoi!$Z:$Z,"Bộ mẫu") | F10: =COUNTIFS(Ngan_hang_cau_hoi!$B:$B,$A10,Ngan_hang_cau_hoi!$F:$F,$B10,Ngan_hang_cau_hoi!$Z:$Z,"Soạn thêm") | G10: =COUNTIFS(Ngan_hang_cau_hoi!$B:$B,$A10,Ngan_hang_cau_hoi!$F:$F,$B10,Ngan_hang_cau_hoi!$S:$S,"<>") | H10: =IFERROR(ROUND(AVERAGEIFS(Ngan_hang_cau_hoi!$T:$T,Ngan_hang_cau_hoi!$B:$B,$A10,Ngan_hang_cau_hoi!$F:$F,$B10),0),0) | I10: =INDEX(Khung_cap_do!$H$2:$H$6,$B10) | J10: =COUNTIFS(Bai_tap_theo_sach!$B:$B,$A10,Bai_tap_theo_sach!$H:$H,$B10)
A11: Tiếng Việt | B11: 4 | C11: Thử thách | D11: =COUNTIFS(Ngan_hang_cau_hoi!$B:$B,$A11,Ngan_hang_cau_hoi!$F:$F,$B11) | E11: =COUNTIFS(Ngan_hang_cau_hoi!$B:$B,$A11,Ngan_hang_cau_hoi!$F:$F,$B11,Ngan_hang_cau_hoi!$Z:$Z,"Bộ mẫu") | F11: =COUNTIFS(Ngan_hang_cau_hoi!$B:$B,$A11,Ngan_hang_cau_hoi!$F:$F,$B11,Ngan_hang_cau_hoi!$Z:$Z,"Soạn thêm") | G11: =COUNTIFS(Ngan_hang_cau_hoi!$B:$B,$A11,Ngan_hang_cau_hoi!$F:$F,$B11,Ngan_hang_cau_hoi!$S:$S,"<>") | H11: =IFERROR(ROUND(AVERAGEIFS(Ngan_hang_cau_hoi!$T:$T,Ngan_hang_cau_hoi!$B:$B,$A11,Ngan_hang_cau_hoi!$F:$F,$B11),0),0) | I11: =INDEX(Khung_cap_do!$H$2:$H$6,$B11) | J11: =COUNTIFS(Bai_tap_theo_sach!$B:$B,$A11,Bai_tap_theo_sach!$H:$H,$B11)
A12: Tiếng Việt | B12: 5 | C12: Mở rộng | D12: =COUNTIFS(Ngan_hang_cau_hoi!$B:$B,$A12,Ngan_hang_cau_hoi!$F:$F,$B12) | E12: =COUNTIFS(Ngan_hang_cau_hoi!$B:$B,$A12,Ngan_hang_cau_hoi!$F:$F,$B12,Ngan_hang_cau_hoi!$Z:$Z,"Bộ mẫu") | F12: =COUNTIFS(Ngan_hang_cau_hoi!$B:$B,$A12,Ngan_hang_cau_hoi!$F:$F,$B12,Ngan_hang_cau_hoi!$Z:$Z,"Soạn thêm") | G12: =COUNTIFS(Ngan_hang_cau_hoi!$B:$B,$A12,Ngan_hang_cau_hoi!$F:$F,$B12,Ngan_hang_cau_hoi!$S:$S,"<>") | H12: =IFERROR(ROUND(AVERAGEIFS(Ngan_hang_cau_hoi!$T:$T,Ngan_hang_cau_hoi!$B:$B,$A12,Ngan_hang_cau_hoi!$F:$F,$B12),0),0) | I12: =INDEX(Khung_cap_do!$H$2:$H$6,$B12) | J12: =COUNTIFS(Bai_tap_theo_sach!$B:$B,$A12,Bai_tap_theo_sach!$H:$H,$B12)
A13: Cộng Tiếng Việt | D13: =SUM(D8:D12) | E13: =SUM(E8:E12) | F13: =SUM(F8:F12) | G13: =SUM(G8:G12) | H13: =IFERROR(ROUND(AVERAGEIFS(Ngan_hang_cau_hoi!$T:$T,Ngan_hang_cau_hoi!$B:$B,"Tiếng Việt"),0),0) | J13: =SUM(J8:J12)
A14: Tiếng Anh | B14: 1 | C14: Làm quen | D14: =COUNTIFS(Ngan_hang_cau_hoi!$B:$B,$A14,Ngan_hang_cau_hoi!$F:$F,$B14) | E14: =COUNTIFS(Ngan_hang_cau_hoi!$B:$B,$A14,Ngan_hang_cau_hoi!$F:$F,$B14,Ngan_hang_cau_hoi!$Z:$Z,"Bộ mẫu") | F14: =COUNTIFS(Ngan_hang_cau_hoi!$B:$B,$A14,Ngan_hang_cau_hoi!$F:$F,$B14,Ngan_hang_cau_hoi!$Z:$Z,"Soạn thêm") | G14: =COUNTIFS(Ngan_hang_cau_hoi!$B:$B,$A14,Ngan_hang_cau_hoi!$F:$F,$B14,Ngan_hang_cau_hoi!$S:$S,"<>") | H14: =IFERROR(ROUND(AVERAGEIFS(Ngan_hang_cau_hoi!$T:$T,Ngan_hang_cau_hoi!$B:$B,$A14,Ngan_hang_cau_hoi!$F:$F,$B14),0),0) | I14: =INDEX(Khung_cap_do!$H$2:$H$6,$B14) | J14: =COUNTIFS(Bai_tap_theo_sach!$B:$B,$A14,Bai_tap_theo_sach!$H:$H,$B14)
A15: Tiếng Anh | B15: 2 | C15: Cơ bản | D15: =COUNTIFS(Ngan_hang_cau_hoi!$B:$B,$A15,Ngan_hang_cau_hoi!$F:$F,$B15) | E15: =COUNTIFS(Ngan_hang_cau_hoi!$B:$B,$A15,Ngan_hang_cau_hoi!$F:$F,$B15,Ngan_hang_cau_hoi!$Z:$Z,"Bộ mẫu") | F15: =COUNTIFS(Ngan_hang_cau_hoi!$B:$B,$A15,Ngan_hang_cau_hoi!$F:$F,$B15,Ngan_hang_cau_hoi!$Z:$Z,"Soạn thêm") | G15: =COUNTIFS(Ngan_hang_cau_hoi!$B:$B,$A15,Ngan_hang_cau_hoi!$F:$F,$B15,Ngan_hang_cau_hoi!$S:$S,"<>") | H15: =IFERROR(ROUND(AVERAGEIFS(Ngan_hang_cau_hoi!$T:$T,Ngan_hang_cau_hoi!$B:$B,$A15,Ngan_hang_cau_hoi!$F:$F,$B15),0),0) | I15: =INDEX(Khung_cap_do!$H$2:$H$6,$B15) | J15: =COUNTIFS(Bai_tap_theo_sach!$B:$B,$A15,Bai_tap_theo_sach!$H:$H,$B15)
A16: Tiếng Anh | B16: 3 | C16: Vận dụng | D16: =COUNTIFS(Ngan_hang_cau_hoi!$B:$B,$A16,Ngan_hang_cau_hoi!$F:$F,$B16) | E16: =COUNTIFS(Ngan_hang_cau_hoi!$B:$B,$A16,Ngan_hang_cau_hoi!$F:$F,$B16,Ngan_hang_cau_hoi!$Z:$Z,"Bộ mẫu") | F16: =COUNTIFS(Ngan_hang_cau_hoi!$B:$B,$A16,Ngan_hang_cau_hoi!$F:$F,$B16,Ngan_hang_cau_hoi!$Z:$Z,"Soạn thêm") | G16: =COUNTIFS(Ngan_hang_cau_hoi!$B:$B,$A16,Ngan_hang_cau_hoi!$F:$F,$B16,Ngan_hang_cau_hoi!$S:$S,"<>") | H16: =IFERROR(ROUND(AVERAGEIFS(Ngan_hang_cau_hoi!$T:$T,Ngan_hang_cau_hoi!$B:$B,$A16,Ngan_hang_cau_hoi!$F:$F,$B16),0),0) | I16: =INDEX(Khung_cap_do!$H$2:$H$6,$B16) | J16: =COUNTIFS(Bai_tap_theo_sach!$B:$B,$A16,Bai_tap_theo_sach!$H:$H,$B16)
A17: Tiếng Anh | B17: 4 | C17: Thử thách | D17: =COUNTIFS(Ngan_hang_cau_hoi!$B:$B,$A17,Ngan_hang_cau_hoi!$F:$F,$B17) | E17: =COUNTIFS(Ngan_hang_cau_hoi!$B:$B,$A17,Ngan_hang_cau_hoi!$F:$F,$B17,Ngan_hang_cau_hoi!$Z:$Z,"Bộ mẫu") | F17: =COUNTIFS(Ngan_hang_cau_hoi!$B:$B,$A17,Ngan_hang_cau_hoi!$F:$F,$B17,Ngan_hang_cau_hoi!$Z:$Z,"Soạn thêm") | G17: =COUNTIFS(Ngan_hang_cau_hoi!$B:$B,$A17,Ngan_hang_cau_hoi!$F:$F,$B17,Ngan_hang_cau_hoi!$S:$S,"<>") | H17: =IFERROR(ROUND(AVERAGEIFS(Ngan_hang_cau_hoi!$T:$T,Ngan_hang_cau_hoi!$B:$B,$A17,Ngan_hang_cau_hoi!$F:$F,$B17),0),0) | I17: =INDEX(Khung_cap_do!$H$2:$H$6,$B17) | J17: =COUNTIFS(Bai_tap_theo_sach!$B:$B,$A17,Bai_tap_theo_sach!$H:$H,$B17)
A18: Tiếng Anh | B18: 5 | C18: Mở rộng | D18: =COUNTIFS(Ngan_hang_cau_hoi!$B:$B,$A18,Ngan_hang_cau_hoi!$F:$F,$B18) | E18: =COUNTIFS(Ngan_hang_cau_hoi!$B:$B,$A18,Ngan_hang_cau_hoi!$F:$F,$B18,Ngan_hang_cau_hoi!$Z:$Z,"Bộ mẫu") | F18: =COUNTIFS(Ngan_hang_cau_hoi!$B:$B,$A18,Ngan_hang_cau_hoi!$F:$F,$B18,Ngan_hang_cau_hoi!$Z:$Z,"Soạn thêm") | G18: =COUNTIFS(Ngan_hang_cau_hoi!$B:$B,$A18,Ngan_hang_cau_hoi!$F:$F,$B18,Ngan_hang_cau_hoi!$S:$S,"<>") | H18: =IFERROR(ROUND(AVERAGEIFS(Ngan_hang_cau_hoi!$T:$T,Ngan_hang_cau_hoi!$B:$B,$A18,Ngan_hang_cau_hoi!$F:$F,$B18),0),0) | I18: =INDEX(Khung_cap_do!$H$2:$H$6,$B18) | J18: =COUNTIFS(Bai_tap_theo_sach!$B:$B,$A18,Bai_tap_theo_sach!$H:$H,$B18)
A19: Cộng Tiếng Anh | D19: =SUM(D14:D18) | E19: =SUM(E14:E18) | F19: =SUM(F14:F18) | G19: =SUM(G14:G18) | H19: =IFERROR(ROUND(AVERAGEIFS(Ngan_hang_cau_hoi!$T:$T,Ngan_hang_cau_hoi!$B:$B,"Tiếng Anh"),0),0) | J19: =SUM(J14:J18)
A20: TỔNG CỘNG | D20: =D7+D13+D19 | E20: =E7+E13+E19 | F20: =F7+F13+F19 | G20: =G7+G13+G19 | H20: =IFERROR(ROUND(AVERAGE(Ngan_hang_cau_hoi!$T:$T),0),0) | J20: =J7+J13+J19
A22: Mọi số liệu là công thức đếm từ sheet Ngan_hang_cau_hoi và Bai_tap_theo_sach.

Sheet Toan_L1-L5
A1: ID | B1: Môn học | C1: Lớp | D1: Giai đoạn gợi ý | E1: Chủ đề / kỹ năng | F1: Cấp độ | G1: Tên cấp độ | H1: Cấp độ cũ (bộ mẫu) | I1: Lý do điều chỉnh cấp độ | J1: Loại câu hỏi | K1: Câu hỏi / nhiệm vụ | L1: Lựa chọn A | M1: Lựa chọn B | N1: Lựa chọn C | O1: Lựa chọn D | P1: Lựa chọn E | Q1: Đáp án đúng | R1: Lời giải / phản hồi | S1: Lời giải chi tiết | T1: Thời gian (giây) | U1: Điểm khi đúng | V1: Đề ôn | W1: Thứ tự trong đề | X1: Mã YCCĐ | Y1: Mã dạng bài | Z1: Nguồn câu | AA1: Bản dùng trong app (nếu khác câu gốc) | AB1: Điều kiện tiên quyết | AC1: Căn cứ chương trình / lưu ý đối chiếu | AD1: Nguồn / phạm vi | AE1: Trạng thái nội dung | AF1: Trạng thái giáo viên | AG1: Ghi chú kiểm duyệt
A2: EC1-001 | B2: Toán | C2: 1 | D2: Sau khi học số tương ứng | E2: Nhận biết số | F2: 1 | G2: Làm quen | J2: Chọn đáp án | K2: Có 3 quả táo. Số quả táo là số nào? | L2: 2 | M2: 3 | N2: 4 | Q2: B | R2: Đếm lần lượt 1, 2, 3 quả; có 3 quả. | T2: 30 | U2: =INDEX(Khung_cap_do!$H$2:$H$6,F2) | V2: 1 | W2: 1 | X2: T1.SO.01 | Y2: TOAN.DEM | Z2: Bộ mẫu | AB2: Đã học nhận biết số 1–3 và đếm đồ vật tương ứng. | AC2: Minh họa yêu cầu nhận biết số và đếm; giáo viên gắn với tiến trình SGK. | AD2: Chương trình GDPT 2018 / kế hoạch dạy học của trường; đối chiếu văn bản hiện hành | AE2: Bản mẫu — cần rà soát | AF2: Chờ giáo viên duyệt
A3: EC1-002 | B3: Toán | C3: 1 | D3: Sau khi học so sánh số | E3: So sánh số | F3: 1 | G3: Làm quen | J3: Chọn đáp án | K3: Số nào bé hơn 4? | L3: 5 | M3: 3 | N3: 6 | Q3: B | R3: 3 bé hơn 4. | T3: 30 | U3: =INDEX(Khung_cap_do!$H$2:$H$6,F3) | V3: 1 | W3: 2 | X3: T1.SO.02 | Y3: TOAN.SOSANH | Z3: Bộ mẫu | AB3: Các số trong lựa chọn và ý niệm so sánh đã được học. | AC3: Bài tập nhận biết quan hệ số trong phạm vi đã học. | AD3: Chương trình GDPT 2018 / kế hoạch dạy học của trường; đối chiếu văn bản hiện hành | AE3: Bản mẫu — cần rà soát | AF3: Chờ giáo viên duyệt
A4: EC1-003 | B4: Toán | C4: 1 | D4: Sau khi học hình dạng | E4: Hình dạng | F4: 1 | G4: Làm quen | J4: Chọn đáp án | K4: Vật nào thường có dạng hình tròn? | L4: Quả bóng | M4: Quyển sách | N4: Hộp vuông | Q4: A | R4: Quả bóng được minh họa bằng dạng tròn. | T4: 30 | U4: =INDEX(Khung_cap_do!$H$2:$H$6,F4) | V4: 2 | W4: 1 | X4: T1.HH.02 | Y4: TOAN.HINH | Z4: Bộ mẫu | AB4: Đã làm quen với hình dạng được dùng. | AC4: Nhận dạng trực quan; hình minh họa phải rõ. | AD4: Chương trình GDPT 2018 / kế hoạch dạy học của trường; đối chiếu văn bản hiện hành | AE4: Bản mẫu — cần rà soát | AF4: Chờ giáo viên duyệt
A5: EC1-046 | B5: Toán | C5: 1 | D5: Sau khi học các số 0–5 | E5: Đếm số lượng | F5: 1 | G5: Làm quen | J5: Chọn đáp án | K5: Đếm số ngôi sao: ⭐⭐⭐⭐⭐ | L5: 4 | M5: 5 | N5: 6 | Q5: B | R5: Đếm lần lượt 1, 2, 3, 4, 5: có 5 ngôi sao. | T5: 30 | U5: =INDEX(Khung_cap_do!$H$2:$H$6,F5) | V5: 2 | W5: 2 | X5: T1.SO.01 | Y5: TOAN.DEM | Z5: Soạn thêm | AB5: Đã học đếm và nhận biết số đến 5. | AC5: Chương trình GDPT 2018 – Toán 1; đối chiếu SGK Kết nối tri thức. | AD5: EduChain Kids soạn thêm (2026-10); bám chương trình GDPT 2018 và trình tự SGK đã chọn | AE5: Bản soạn mới — cần rà soát | AF5: Chờ giáo viên duyệt
A6: EC1-047 | B6: Toán | C6: 1 | D6: Sau khi học so sánh số | E6: So sánh số | F6: 1 | G6: Làm quen | J6: Đúng / Sai | K6: Số 7 lớn hơn số 5. | L6: Đúng | M6: Sai | Q6: A | R6: Đếm 5, 6, 7: số 7 đứng sau số 5 nên 7 lớn hơn 5. | T6: 30 | U6: =INDEX(Khung_cap_do!$H$2:$H$6,F6) | V6: 3 | W6: 1 | X6: T1.SO.02 | Y6: TOAN.DUNGSAI | Z6: Soạn thêm | AB6: Đã học so sánh các số trong phạm vi 10. | AC6: Chương trình GDPT 2018 – Toán 1; đối chiếu SGK Kết nối tri thức. | AD6: EduChain Kids soạn thêm (2026-10); bám chương trình GDPT 2018 và trình tự SGK đã chọn | AE6: Bản soạn mới — cần rà soát | AF6: Chờ giáo viên duyệt
A7: EC1-048 | B7: Toán | C7: 1 | D7: Sau khi học hình phẳng | E7: Hình dạng | F7: 1 | G7: Làm quen | J7: Chọn đáp án | K7: Hình nào có 3 cạnh? | L7: Hình tam giác | M7: Hình vuông | N7: Hình tròn | Q7: A | R7: Hình tam giác có 3 cạnh. | T7: 30 | U7: =INDEX(Khung_cap_do!$H$2:$H$6,F7) | V7: 3 | W7: 2 | X7: T1.HH.02 | Y7: TOAN.HINH | Z7: Soạn thêm | AB7: Đã học hình vuông, hình tròn, hình tam giác. | AC7: Chương trình GDPT 2018 – Toán 1; đối chiếu SGK Kết nối tri thức. | AD7: EduChain Kids soạn thêm (2026-10); bám chương trình GDPT 2018 và trình tự SGK đã chọn | AE7: Bản soạn mới — cần rà soát | AF7: Chờ giáo viên duyệt
A8: EC1-049 | B8: Toán | C8: 1 | D8: Sau khi học các số 0–10 | E8: Thứ tự số | F8: 1 | G8: Làm quen | J8: Điền đáp án | K8: Đếm tiếp: 4, 5, 6, ... Số tiếp theo là số mấy? | Q8: 7 / bảy | R8: Đếm tiếp sau 6 là 7. | T8: 40 | U8: =INDEX(Khung_cap_do!$H$2:$H$6,F8) | V8: 4 | W8: 1 | X8: T1.SO.01 | Y8: TOAN.SOTHIEU | Z8: Soạn thêm | AB8: Đã học đếm đến 10. | AC8: Chương trình GDPT 2018 – Toán 1; đối chiếu SGK Kết nối tri thức. | AD8: EduChain Kids soạn thêm (2026-10); bám chương trình GDPT 2018 và trình tự SGK đã chọn | AE8: Bản soạn mới — cần rà soát | AF8: Chờ giáo viên duyệt
A9: EC1-050 | B9: Toán | C9: 1 | D9: Sau khi học số 0 | E9: Số 0 | F9: 1 | G9: Làm quen | J9: Chọn đáp án | K9: Trong đĩa không có quả nào. Số quả trong đĩa là số mấy? | L9: 0 | M9: 1 | N9: 2 | Q9: A | R9: Không có quả nào thì viết số 0. | T9: 30 | U9: =INDEX(Khung_cap_do!$H$2:$H$6,F9) | V9: 4 | W9: 2 | X9: T1.SO.01 | Y9: TOAN.DEM | Z9: Soạn thêm | AB9: Đã học số 0. | AC9: Chương trình GDPT 2018 – Toán 1; đối chiếu SGK Kết nối tri thức. | AD9: EduChain Kids soạn thêm (2026-10); bám chương trình GDPT 2018 và trình tự SGK đã chọn | AE9: Bản soạn mới — cần rà soát | AF9: Chờ giáo viên duyệt
A10: EC1-004 | B10: Toán | C10: 1 | D10: Sau khi học phép cộng phù hợp | E10: Phép cộng | F10: 2 | G10: Cơ bản | J10: Điền đáp án | K10: 2 + 1 = ? | Q10: 3 | R10: Có 2 đồ vật, thêm 1 thì có 3. | T10: 50 | U10: =INDEX(Khung_cap_do!$H$2:$H$6,F10) | V10: 1 | W10: 3 | X10: T1.PT.02 | Y10: TOAN.TINH | Z10: Bộ mẫu | AB10: Đã học phép cộng với các số này. | AC10: Chỉ dùng khi phép tính đã được dạy. | AD10: Chương trình GDPT 2018 / kế hoạch dạy học của trường; đối chiếu văn bản hiện hành | AE10: Bản mẫu — cần rà soát | AF10: Chờ giáo viên duyệt
A11: EC1-005 | B11: Toán | C11: 1 | D11: Sau khi học so sánh | E11: So sánh số lượng | F11: 2 | G11: Cơ bản | J11: Chọn đáp án | K11: Nhóm 5 con cá và nhóm 3 con cá. Nhóm nào nhiều hơn? | L11: Nhóm 5 con | M11: Nhóm 3 con | N11: Bằng nhau | Q11: A | R11: 5 nhiều hơn 3. | T11: 40 | U11: =INDEX(Khung_cap_do!$H$2:$H$6,F11) | V11: 1 | W11: 4 | X11: T1.SO.02 | Y11: TOAN.SOSANH | Z11: Bộ mẫu | AB11: Đã học đếm và so sánh trong phạm vi tương ứng. | AC11: Tình huống quen thuộc, không cần kiến thức mới. | AD11: Chương trình GDPT 2018 / kế hoạch dạy học của trường; đối chiếu văn bản hiện hành | AE11: Bản mẫu — cần rà soát | AF11: Chờ giáo viên duyệt
A12: EC1-006 | B12: Toán | C12: 1 | D12: Sau khi học phép trừ phù hợp | E12: Phép trừ | F12: 2 | G12: Cơ bản | J12: Điền đáp án | K12: 4 − 1 = ? | Q12: 3 | R12: Bớt 1 từ 4 còn 3. | T12: 50 | U12: =INDEX(Khung_cap_do!$H$2:$H$6,F12) | V12: 2 | W12: 3 | X12: T1.PT.02 | Y12: TOAN.TINH | Z12: Bộ mẫu | AB12: Đã học phép trừ với các số này. | AC12: Điều chỉnh phạm vi số theo tiến trình. | AD12: Chương trình GDPT 2018 / kế hoạch dạy học của trường; đối chiếu văn bản hiện hành | AE12: Bản mẫu — cần rà soát | AF12: Chờ giáo viên duyệt
A13: EC1-051 | B13: Toán | C13: 1 | D13: Sau khi học phép cộng trong phạm vi 10 | E13: Phép cộng | F13: 2 | G13: Cơ bản | J13: Điền đáp án | K13: 3 + 4 = ? | Q13: 7 / bảy | R13: 3 thêm 4 là 7. | T13: 50 | U13: =INDEX(Khung_cap_do!$H$2:$H$6,F13) | V13: 2 | W13: 4 | X13: T1.PT.02 | Y13: TOAN.TINH | Z13: Soạn thêm | AB13: Đã học cộng trong phạm vi 10. | AC13: Chương trình GDPT 2018 – Toán 1; đối chiếu SGK Kết nối tri thức. | AD13: EduChain Kids soạn thêm (2026-10); bám chương trình GDPT 2018 và trình tự SGK đã chọn | AE13: Bản soạn mới — cần rà soát | AF13: Chờ giáo viên duyệt
A14: EC1-052 | B14: Toán | C14: 1 | D14: Sau khi học phép trừ trong phạm vi 10 | E14: Phép trừ | F14: 2 | G14: Cơ bản | J14: Điền đáp án | K14: 9 − 5 = ? | Q14: 4 / bốn | R14: 9 bớt 5 còn 4. | T14: 50 | U14: =INDEX(Khung_cap_do!$H$2:$H$6,F14) | V14: 3 | W14: 3 | X14: T1.PT.02 | Y14: TOAN.TINH | Z14: Soạn thêm | AB14: Đã học trừ trong phạm vi 10. | AC14: Chương trình GDPT 2018 – Toán 1; đối chiếu SGK Kết nối tri thức. | AD14: EduChain Kids soạn thêm (2026-10); bám chương trình GDPT 2018 và trình tự SGK đã chọn | AE14: Bản soạn mới — cần rà soát | AF14: Chờ giáo viên duyệt
A15: EC1-053 | B15: Toán | C15: 1 | D15: Sau khi học dấu >, <, = | E15: So sánh số | F15: 2 | G15: Cơ bản | J15: Chọn đáp án | K15: Chọn dấu đúng: 6 ... 8 | L15: > | M15: < | N15: = | Q15: B | R15: 6 bé hơn 8 nên điền dấu <. | T15: 40 | U15: =INDEX(Khung_cap_do!$H$2:$H$6,F15) | V15: 3 | W15: 4 | X15: T1.SO.02 | Y15: TOAN.SOSANH | Z15: Soạn thêm | AB15: Đã học các dấu >, <, =. | AC15: Chương trình GDPT 2018 – Toán 1; đối chiếu SGK Kết nối tri thức. | AD15: EduChain Kids soạn thêm (2026-10); bám chương trình GDPT 2018 và trình tự SGK đã chọn | AE15: Bản soạn mới — cần rà soát | AF15: Chờ giáo viên duyệt
A16: EC1-054 | B16: Toán | C16: 1 | D16: Sau khi học so sánh, xếp thứ tự số | E16: Xếp thứ tự số | F16: 2 | G16: Cơ bản | J16: Sắp xếp | K16: Xếp các số theo thứ tự từ bé đến lớn. (Các mục: 2 / 5 / 7 / 9) | Q16: 2 → 5 → 7 → 9 | R16: Từ bé đến lớn: 2, 5, 7, 9. | T16: 55 | U16: =INDEX(Khung_cap_do!$H$2:$H$6,F16) | V16: 4 | W16: 3 | X16: T1.SO.02 | Y16: TOAN.SAPXEP | Z16: Soạn thêm | AB16: Đã học so sánh số trong phạm vi 10. | AC16: Chương trình GDPT 2018 – Toán 1; đối chiếu SGK Kết nối tri thức. | AD16: EduChain Kids soạn thêm (2026-10); bám chương trình GDPT 2018 và trình tự SGK đã chọn | AE16: Bản soạn mới — cần rà soát | AF16: Chờ giáo viên duyệt
A17: EC1-055 | B17: Toán | C17: 1 | D17: Sau khi học cộng, trừ trong phạm vi 10 | E17: Tính nhẩm | F17: 2 | G17: Cơ bản | J17: Chọn đáp án | K17: Phép tính nào có kết quả bằng 5? | L17: 2 + 3 | M17: 4 + 2 | N17: 6 − 2 | Q17: A | R17: 2 + 3 = 5; 4 + 2 = 6; 6 − 2 = 4. | T17: 40 | U17: =INDEX(Khung_cap_do!$H$2:$H$6,F17) | V17: 4 | W17: 4 | X17: T1.PT.02 | Y17: TOAN.TINH | Z17: Soạn thêm | AB17: Đã học cộng, trừ trong phạm vi 10. | AC17: Chương trình GDPT 2018 – Toán 1; đối chiếu SGK Kết nối tri thức. | AD17: EduChain Kids soạn thêm (2026-10); bám chương trình GDPT 2018 và trình tự SGK đã chọn | AE17: Bản soạn mới — cần rà soát | AF17: Chờ giáo viên duyệt
A18: EC1-007 | B18: Toán | C18: 1 | D18: Sau khi học cộng tương ứng | E18: Toán có lời văn | F18: 3 | G18: Vận dụng | J18: Điền đáp án | K18: Mai có 2 bút chì, được tặng thêm 2. Mai có tất cả bao nhiêu bút chì? | Q18: 4 | R18: Thêm vào nên tính 2 + 2 = 4. | S18: Được tặng thêm là gộp lại, ta làm phép cộng: 2 + 2 = 4. Mai có 4 bút chì. | T18: 70 | U18: =INDEX(Khung_cap_do!$H$2:$H$6,F18) | V18: 1 | W18: 5 | X18: T1.PT.03 | Y18: TOAN.LOIVAN | Z18: Bộ mẫu | AB18: Đã học phép cộng 2 + 2 và tình huống thêm vào. | AC18: Vận dụng kiến thức trong tình huống quen thuộc. | AD18: Chương trình GDPT 2018 / kế hoạch dạy học của trường; đối chiếu văn bản hiện hành | AE18: Bản mẫu — cần rà soát | AF18: Chờ giáo viên duyệt
A19: EC1-008 | B19: Toán | C19: 1 | D19: Sau khi học trừ tương ứng | E19: Toán có lời văn | F19: 3 | G19: Vận dụng | J19: Điền đáp án | K19: Có 5 con chim, 2 con bay đi. Còn lại bao nhiêu con? | Q19: 3 | R19: Bớt đi nên tính 5 − 2 = 3. | S19: Bay đi là bớt đi, ta làm phép trừ: 5 − 2 = 3. Còn lại 3 con chim. | T19: 60 | U19: =INDEX(Khung_cap_do!$H$2:$H$6,F19) | V19: 1 | W19: 6 | X19: T1.PT.03 | Y19: TOAN.LOIVAN | Z19: Bộ mẫu | AB19: Đã học phép trừ 5 − 2. | AC19: Chỉ phát hành khi phù hợp tiến trình lớp. | AD19: Chương trình GDPT 2018 / kế hoạch dạy học của trường; đối chiếu văn bản hiện hành | AE19: Bản mẫu — cần rà soát | AF19: Chờ giáo viên duyệt
A20: EC1-009 | B20: Toán | C20: 1 | D20: Sau khi học tách/gộp số | E20: Tách và gộp số | F20: 3 | G20: Vận dụng | J20: Điền đáp án | K20: Có 5 khối gỗ, 2 khối đỏ, còn lại xanh. Có mấy khối xanh? | Q20: 3 | R20: 5 − 2 = 3. | S20: Lấy tất cả trừ đi số khối đỏ: 5 − 2 = 3. Có 3 khối xanh. | T20: 60 | U20: =INDEX(Khung_cap_do!$H$2:$H$6,F20) | V20: 2 | W20: 5 | X20: T1.PT.03 | Y20: TOAN.LOIVAN | Z20: Bộ mẫu | AB20: Đã học tách/gộp hoặc phép trừ tương ứng. | AC20: Giáo viên rà soát mạch kiến thức. | AD20: Chương trình GDPT 2018 / kế hoạch dạy học của trường; đối chiếu văn bản hiện hành | AE20: Bản mẫu — cần rà soát | AF20: Chờ giáo viên duyệt
A21: EC1-012 | B21: Toán | C21: 1 | D21: Sau khi học phép cộng phù hợp | E21: Giải quyết vấn đề | F21: 3 | G21: Vận dụng | H21: 4 | I21: Cùng dạng "thêm vào" với EC1-007 (một phép tính), nên xếp L3. | J21: Điền đáp án | K21: Có 2 con vịt, 3 con đi tới. Có tất cả bao nhiêu con? | Q21: 5 | R21: Có thêm vịt: 2 + 3 = 5. | S21: Đi tới là thêm vào: 2 + 3 = 5. Có tất cả 5 con vịt. | T21: 60 | U21: =INDEX(Khung_cap_do!$H$2:$H$6,F21) | V21: 2 | W21: 6 | X21: T1.PT.03 | Y21: TOAN.LOIVAN | Z21: Bộ mẫu | AB21: Đã học phép cộng 2 + 3. | AC21: Không dùng nếu phép tính chưa được dạy. | AD21: Chương trình GDPT 2018 / kế hoạch dạy học của trường; đối chiếu văn bản hiện hành | AE21: Bản mẫu — cần rà soát | AF21: Chờ giáo viên duyệt
A22: EC1-015 | B22: Toán | C22: 1 | D22: Ôn tập cuối giai đoạn | E22: Tổng hợp | F22: 3 | G22: Vận dụng | H22: 5 | I22: Chỉ cần một phép trừ quen thuộc, chưa phải tình huống mở rộng; xếp L3. | J22: Chọn đáp án | K22: Có 6 chiếc lá, 2 chiếc rơi xuống. Còn lại bao nhiêu? | L22: 8 | M22: 4 | N22: 3 | Q22: B | R22: 6 − 2 = 4. | S22: Rơi xuống là bớt đi: 6 − 2 = 4. Còn lại 4 chiếc lá. | T22: 50 | U22: =INDEX(Khung_cap_do!$H$2:$H$6,F22) | V22: 3 | W22: 5 | X22: T1.PT.03 | Y22: TOAN.LOIVAN | Z22: Bộ mẫu | AB22: Đã học phép trừ 6 − 2. | AC22: Chỉ dùng nếu tất cả kiến thức đã được học. | AD22: Chương trình GDPT 2018 / kế hoạch dạy học của trường; đối chiếu văn bản hiện hành | AE22: Bản mẫu — cần rà soát | AF22: Chờ giáo viên duyệt
A23: EC1-056 | B23: Toán | C23: 1 | D23: Sau khi học phép cộng trong phạm vi 10 | E23: Toán có lời văn | F23: 3 | G23: Vận dụng | J23: Điền đáp án | K23: Trong vườn có 6 cây cam và 3 cây bưởi. Vườn có tất cả bao nhiêu cây? | Q23: 9 / chín | R23: 6 + 3 = 9. | S23: Gộp cây cam và cây bưởi: 6 + 3 = 9. Vườn có 9 cây. | T23: 70 | U23: =INDEX(Khung_cap_do!$H$2:$H$6,F23) | V23: 3 | W23: 6 | X23: T1.PT.03 | Y23: TOAN.LOIVAN | Z23: Soạn thêm | AB23: Đã học cộng trong phạm vi 10. | AC23: Chương trình GDPT 2018 – Toán 1; đối chiếu SGK Kết nối tri thức. | AD23: EduChain Kids soạn thêm (2026-10); bám chương trình GDPT 2018 và trình tự SGK đã chọn | AE23: Bản soạn mới — cần rà soát | AF23: Chờ giáo viên duyệt
A24: EC1-057 | B24: Toán | C24: 1 | D24: Sau khi học phép trừ trong phạm vi 10 | E24: Toán có lời văn | F24: 3 | G24: Vận dụng | J24: Điền đáp án | K24: Bình có 8 cái kẹo, Bình cho em 3 cái. Bình còn lại mấy cái kẹo? | Q24: 5 / năm | R24: 8 − 3 = 5. | S24: Cho em là bớt đi: 8 − 3 = 5. Bình còn 5 cái kẹo. | T24: 70 | U24: =INDEX(Khung_cap_do!$H$2:$H$6,F24) | V24: 4 | W24: 5 | X24: T1.PT.03 | Y24: TOAN.LOIVAN | Z24: Soạn thêm | AB24: Đã học trừ trong phạm vi 10. | AC24: Chương trình GDPT 2018 – Toán 1; đối chiếu SGK Kết nối tri thức. | AD24: EduChain Kids soạn thêm (2026-10); bám chương trình GDPT 2018 và trình tự SGK đã chọn | AE24: Bản soạn mới — cần rà soát | AF24: Chờ giáo viên duyệt
A25: EC1-058 | B25: Toán | C25: 1 | D25: Sau khi học cộng, trừ trong phạm vi 10 | E25: Tính nhẩm | F25: 3 | G25: Vận dụng | J25: Chọn nhiều đáp án | K25: Chọn TẤT CẢ phép tính có kết quả bằng 6. | L25: 3 + 3 | M25: 4 + 2 | N25: 9 − 2 | O25: 10 − 4 | Q25: A, B, D | R25: 3 + 3 = 6; 4 + 2 = 6; 10 − 4 = 6; còn 9 − 2 = 7. | S25: Tính từng phép: 3 + 3 = 6, 4 + 2 = 6, 9 − 2 = 7, 10 − 4 = 6. Chọn 3 phép có kết quả 6. | T25: 60 | U25: =INDEX(Khung_cap_do!$H$2:$H$6,F25) | V25: 4 | W25: 6 | X25: T1.PT.02 | Y25: TOAN.TINH | Z25: Soạn thêm | AB25: Đã học cộng, trừ trong phạm vi 10. | AC25: Chương trình GDPT 2018 – Toán 1; đối chiếu SGK Kết nối tri thức. | AD25: EduChain Kids soạn thêm (2026-10); bám chương trình GDPT 2018 và trình tự SGK đã chọn | AE25: Bản soạn mới — cần rà soát | AF25: Chờ giáo viên duyệt
A26: EC1-010 | B26: Toán | C26: 1 | D26: Sau khi học cộng phù hợp | E26: Chọn phép tính | F26: 4 | G26: Thử thách | J26: Chọn đáp án | K26: An có 3 viên bi, Bình có 2 viên. Cả hai có bao nhiêu viên? | L26: 3 − 2 = 1 | M26: 3 + 2 = 5 | N26: 3 = 2 | Q26: B | R26: Gộp số bi: 3 + 2 = 5. | S26: "Cả hai" là gộp lại, ta chọn phép cộng: 3 + 2 = 5. | T26: 60 | U26: =INDEX(Khung_cap_do!$H$2:$H$6,F26) | V26: 1 | W26: 7 | X26: T1.PT.07 | Y26: TOAN.LOIVAN | Z26: Bộ mẫu | AB26: Đã học cộng trong phạm vi 5. | AC26: Khó hơn ở việc chọn phép tính, không phải kiến thức mới. | AD26: Chương trình GDPT 2018 / kế hoạch dạy học của trường; đối chiếu văn bản hiện hành | AE26: Bản mẫu — cần rà soát | AF26: Chờ giáo viên duyệt
A27: EC1-011 | B27: Toán | C27: 1 | D27: Sau khi học dãy số | E27: Quy luật | F27: 4 | G27: Thử thách | J27: Chọn đáp án | K27: Dãy 1, 2, 1, 2, __. Số tiếp theo là gì? | L27: 1 | M27: 3 | N27: 4 | Q27: A | R27: Dãy lặp lại 1 rồi 2. | S27: Các số lặp lại theo nhóm "1, 2". Sau 2 lại là 1. | T27: 60 | U27: =INDEX(Khung_cap_do!$H$2:$H$6,F27) | V27: 1 | W27: 8 | X27: T1.SO.01 | Y27: TOAN.SOTHIEU | Z27: Bộ mẫu | AB27: Đọc được các số trong dãy. | AC27: Bài mở rộng; không thay thế nội dung cốt lõi. | AD27: Chương trình GDPT 2018 / kế hoạch dạy học của trường; đối chiếu văn bản hiện hành | AE27: Bản mẫu — cần rà soát | AF27: Chờ giáo viên duyệt
A28: EC1-059 | B28: Toán | C28: 1 | D28: Sau khi học phép trừ trong phạm vi 10 | E28: Chọn phép tính | F28: 4 | G28: Thử thách | J28: Chọn đáp án | K28: Có 7 bạn đang chơi, 2 bạn về nhà. Phép tính nào đúng? | L28: 7 + 2 = 9 | M28: 7 − 2 = 5 | N28: 5 − 2 = 3 | Q28: B | R28: Về nhà là bớt đi: 7 − 2 = 5. | S28: Lúc đầu có 7 bạn, 2 bạn về nhà nên bớt đi 2: 7 − 2 = 5. | T28: 60 | U28: =INDEX(Khung_cap_do!$H$2:$H$6,F28) | V28: 2 | W28: 7 | X28: T1.PT.07 | Y28: TOAN.LOIVAN | Z28: Soạn thêm | AB28: Đã học trừ và bài toán có lời văn đơn giản. | AC28: Chương trình GDPT 2018 – Toán 1; đối chiếu SGK Kết nối tri thức. | AD28: EduChain Kids soạn thêm (2026-10); bám chương trình GDPT 2018 và trình tự SGK đã chọn | AE28: Bản soạn mới — cần rà soát | AF28: Chờ giáo viên duyệt
A29: EC1-060 | B29: Toán | C29: 1 | D29: Sau khi học phép cộng trong phạm vi 10 | E29: Tìm số còn thiếu | F29: 4 | G29: Thử thách | J29: Điền đáp án | K29: Điền số còn thiếu: 3 + ... = 8 | Q29: 5 / năm | R29: 3 + 5 = 8. | S29: Đếm thêm từ 3 đến 8: 4, 5, 6, 7, 8 là 5 bước. Vậy 3 + 5 = 8. | T29: 70 | U29: =INDEX(Khung_cap_do!$H$2:$H$6,F29) | V29: 2 | W29: 8 | X29: T1.PT.02 | Y29: TOAN.SOTHIEU | Z29: Soạn thêm | AB29: Đã học cộng trong phạm vi 10. | AC29: Chương trình GDPT 2018 – Toán 1; đối chiếu SGK Kết nối tri thức. | AD29: EduChain Kids soạn thêm (2026-10); bám chương trình GDPT 2018 và trình tự SGK đã chọn | AE29: Bản soạn mới — cần rà soát | AF29: Chờ giáo viên duyệt
A30: EC1-061 | B30: Toán | C30: 1 | D30: Sau khi học các số 0–10 | E30: Quy luật dãy số | F30: 4 | G30: Thử thách | J30: Điền đáp án | K30: Dãy số: 2, 4, 6, ... Số tiếp theo là số mấy? | Q30: 8 / tám | R30: Mỗi lần thêm 2: 6 + 2 = 8. | S30: 2 lên 4 thêm 2, 4 lên 6 thêm 2. Vậy sau 6 là 6 + 2 = 8. | T30: 70 | U30: =INDEX(Khung_cap_do!$H$2:$H$6,F30) | V30: 3 | W30: 7 | X30: T1.SO.01 | Y30: TOAN.SOTHIEU | Z30: Soạn thêm | AB30: Đã học đếm, cộng trong phạm vi 10. | AC30: Chương trình GDPT 2018 – Toán 1; đối chiếu SGK Kết nối tri thức. | AD30: EduChain Kids soạn thêm (2026-10); bám chương trình GDPT 2018 và trình tự SGK đã chọn | AE30: Bản soạn mới — cần rà soát | AF30: Chờ giáo viên duyệt
A31: EC1-062 | B31: Toán | C31: 1 | D31: Sau khi học cộng, trừ trong phạm vi 10 | E31: So sánh kết quả phép tính | F31: 4 | G31: Thử thách | J31: Đúng / Sai | K31: 4 + 3 = 9 − 2 | L31: Đúng | M31: Sai | Q31: A | R31: 4 + 3 = 7 và 9 − 2 = 7, hai bên bằng nhau. | S31: Tính bên trái: 4 + 3 = 7. Tính bên phải: 9 − 2 = 7. Hai bên đều bằng 7 nên đúng. | T31: 60 | U31: =INDEX(Khung_cap_do!$H$2:$H$6,F31) | V31: 3 | W31: 8 | X31: T1.PT.02 | Y31: TOAN.DUNGSAI | Z31: Soạn thêm | AB31: Đã học cộng, trừ trong phạm vi 10. | AC31: Chương trình GDPT 2018 – Toán 1; đối chiếu SGK Kết nối tri thức. | AD31: EduChain Kids soạn thêm (2026-10); bám chương trình GDPT 2018 và trình tự SGK đã chọn | AE31: Bản soạn mới — cần rà soát | AF31: Chờ giáo viên duyệt
A32: EC1-063 | B32: Toán | C32: 1 | D32: Sau khi học tính có hai dấu phép tính | E32: Toán có lời văn hai bước | F32: 4 | G32: Thử thách | J32: Điền đáp án | K32: Có 10 quả táo. Mẹ biếu bà 3 quả, cho bé 2 quả. Còn lại mấy quả? | Q32: 5 / năm | R32: 10 − 3 − 2 = 5. | S32: Biếu bà 3 quả: 10 − 3 = 7. Cho bé 2 quả: 7 − 2 = 5. Còn lại 5 quả. | T32: 80 | U32: =INDEX(Khung_cap_do!$H$2:$H$6,F32) | V32: 4 | W32: 7 | X32: T1.PT.06 | Y32: TOAN.LOIVAN | Z32: Soạn thêm | AB32: Đã làm quen phép tính có hai dấu. | AC32: Chương trình GDPT 2018 – Toán 1; đối chiếu SGK Kết nối tri thức. | AD32: EduChain Kids soạn thêm (2026-10); bám chương trình GDPT 2018 và trình tự SGK đã chọn | AE32: Bản soạn mới — cần rà soát | AF32: Chờ giáo viên duyệt
A33: EC1-064 | B33: Toán | C33: 1 | D33: Sau khi học phép cộng trong phạm vi 10 | E33: Lập phép tính | F33: 4 | G33: Thử thách | J33: Chọn đáp án | K33: Dùng 3 số 2, 5, 7 lập phép tính đúng. | L33: 2 + 5 = 7 | M33: 5 + 7 = 2 | N33: 2 + 7 = 5 | Q33: A | R33: 2 + 5 = 7 là phép tính đúng. | S33: Thử từng phép: 2 + 5 = 7 đúng; 5 + 7 không bằng 2; 2 + 7 không bằng 5. | T33: 60 | U33: =INDEX(Khung_cap_do!$H$2:$H$6,F33) | V33: 4 | W33: 8 | X33: T1.PT.02 | Y33: TOAN.TINH | Z33: Soạn thêm | AB33: Đã học cộng trong phạm vi 10. | AC33: Chương trình GDPT 2018 – Toán 1; đối chiếu SGK Kết nối tri thức. | AD33: EduChain Kids soạn thêm (2026-10); bám chương trình GDPT 2018 và trình tự SGK đã chọn | AE33: Bản soạn mới — cần rà soát | AF33: Chờ giáo viên duyệt
A34: EC1-013 | B34: Toán | C34: 1 | D34: Sau khi học tách/gộp số | E34: Lập luận số | F34: 5 | G34: Mở rộng | J34: Trả lời ngắn | K34: Có 5 khối. Chia thành 2 nhóm, mỗi nhóm ít nhất 1 khối. Nêu một cách chia. | Q34: Ví dụ: 1 và 4; 2 và 3. | R34: Chấp nhận mọi cách chia hợp lệ thành hai nhóm không rỗng. | S34: Hai nhóm gộp lại phải bằng 5: 1 + 4 = 5, 2 + 3 = 5. Còn 2 + 2 = 4 và 3 + 3 = 6 không đúng. | T34: 95 | U34: =INDEX(Khung_cap_do!$H$2:$H$6,F34) | V34: 1 | W34: 9 | X34: T1.PT.01 | Y34: TOAN.TINH | Z34: Bộ mẫu | AA34: [Chọn nhiều đáp án] Có 5 khối, chia thành 2 nhóm (mỗi nhóm ít nhất 1 khối). Chọn TẤT CẢ cách chia đúng. A. 1 và 4 | B. 2 và 3 | C. 2 và 2 | D. 3 và 3 Đáp án: A, B Ghi chú: Bản app chuyển câu trả lời mở thành "chọn tất cả cách chia đúng" để chấm tự động. | AB34: Đã học tách/gộp số. | AC34: Mở rộng nội bộ; cần rubric, không phải chuẩn chính thức. | AD34: Chương trình GDPT 2018 / kế hoạch dạy học của trường; đối chiếu văn bản hiện hành | AE34: Bản mẫu — cần rà soát | AF34: Chờ giáo viên duyệt
A35: EC1-014 | B35: Toán | C35: 1 | D35: Sau khi học quan hệ số lượng | E35: Chọn chiến lược | F35: 5 | G35: Mở rộng | J35: Trả lời ngắn | K35: Có 4 chiếc cốc và 3 bông hoa. Còn thiếu mấy bông để mỗi cốc có một bông? | Q35: 1 | R35: 4 − 3 = 1; còn thiếu 1 bông. | S35: Cắm mỗi cốc một bông: 3 bông cắm được 3 cốc, còn 1 cốc chưa có hoa. 4 − 3 = 1. | T35: 95 | U35: =INDEX(Khung_cap_do!$H$2:$H$6,F35) | V35: 1 | W35: 10 | X35: T1.PT.03 | Y35: TOAN.LOIVAN | Z35: Bộ mẫu | AA35: [Điền đáp án] Có 4 chiếc cốc và 3 bông hoa. Còn thiếu mấy bông để mỗi cốc có một bông? Đáp án: 1 / một Ghi chú: Bản app chấm theo dạng điền số (chấp nhận "1" hoặc "một"). | AB35: Đã học đếm và quan hệ số lượng tương ứng. | AC35: Tình huống mở rộng trên kiến thức đã học. | AD35: Chương trình GDPT 2018 / kế hoạch dạy học của trường; đối chiếu văn bản hiện hành | AE35: Bản mẫu — cần rà soát | AF35: Chờ giáo viên duyệt
A36: EC1-065 | B36: Toán | C36: 1 | D36: Sau khi học tách, gộp số | E36: Tách – gộp số | F36: 5 | G36: Mở rộng | J36: Chọn nhiều đáp án | K36: Chọn TẤT CẢ cặp số cộng lại bằng 7. | L36: 1 và 6 | M36: 2 và 5 | N36: 3 và 3 | O36: 4 và 3 | Q36: A, B, D | R36: 1 + 6 = 7; 2 + 5 = 7; 4 + 3 = 7; còn 3 + 3 = 6. | S36: Cộng từng cặp: 1 + 6 = 7, 2 + 5 = 7, 3 + 3 = 6, 4 + 3 = 7. | T36: 85 | U36: =INDEX(Khung_cap_do!$H$2:$H$6,F36) | V36: 2 | W36: 9 | X36: T1.PT.02 | Y36: TOAN.TINH | Z36: Soạn thêm | AB36: Đã học cộng trong phạm vi 10. | AC36: Chương trình GDPT 2018 – Toán 1; đối chiếu SGK Kết nối tri thức. | AD36: EduChain Kids soạn thêm (2026-10); bám chương trình GDPT 2018 và trình tự SGK đã chọn | AE36: Bản soạn mới — cần rà soát | AF36: Chờ giáo viên duyệt
A37: EC1-066 | B37: Toán | C37: 1 | D37: Sau khi học cộng, trừ trong phạm vi 10 | E37: Lập luận số | F37: 5 | G37: Mở rộng | J37: Điền đáp án | K37: Nam nghĩ một số. Lấy số đó cộng 3 thì được 9. Nam nghĩ số mấy? | Q37: 6 / sáu | R37: 6 + 3 = 9. | S37: Ta cần số ... + 3 = 9. Lấy 9 − 3 = 6. Thử lại: 6 + 3 = 9. | T37: 95 | U37: =INDEX(Khung_cap_do!$H$2:$H$6,F37) | V37: 2 | W37: 10 | X37: T1.PT.02 | Y37: TOAN.SOTHIEU | Z37: Soạn thêm | AB37: Đã học quan hệ cộng – trừ. | AC37: Chương trình GDPT 2018 – Toán 1; đối chiếu SGK Kết nối tri thức. | AD37: EduChain Kids soạn thêm (2026-10); bám chương trình GDPT 2018 và trình tự SGK đã chọn | AE37: Bản soạn mới — cần rà soát | AF37: Chờ giáo viên duyệt
A38: EC1-067 | B38: Toán | C38: 1 | D38: Sau khi học vị trí trước – sau | E38: Vị trí, thứ tự | F38: 5 | G38: Mở rộng | J38: Chọn đáp án | K38: Có 6 bạn xếp hàng. Mai đứng thứ 2 tính từ đầu hàng. Sau Mai có mấy bạn? | L38: 3 | M38: 4 | N38: 5 | Q38: B | R38: Trước Mai có 1 bạn, Mai là 1 bạn: 6 − 2 = 4. | S38: Tính từ đầu hàng có bạn thứ nhất và Mai là 2 bạn. Còn lại 6 − 2 = 4 bạn đứng sau Mai. | T38: 85 | U38: =INDEX(Khung_cap_do!$H$2:$H$6,F38) | V38: 3 | W38: 9 | X38: T1.HH.01 | Y38: TOAN.LOIVAN | Z38: Soạn thêm | AB38: Đã học trước – sau và trừ trong phạm vi 10. | AC38: Chương trình GDPT 2018 – Toán 1; đối chiếu SGK Kết nối tri thức. | AD38: EduChain Kids soạn thêm (2026-10); bám chương trình GDPT 2018 và trình tự SGK đã chọn | AE38: Bản soạn mới — cần rà soát | AF38: Chờ giáo viên duyệt
A39: EC1-068 | B39: Toán | C39: 1 | D39: Sau khi học cộng, trừ trong phạm vi 10 | E39: Tìm số còn thiếu | F39: 5 | G39: Mở rộng | J39: Điền đáp án | K39: Điền số: 10 − ... = 4 + 2 | Q39: 4 / bốn | R39: 4 + 2 = 6 và 10 − 4 = 6. | S39: Tính bên phải: 4 + 2 = 6. Cần 10 − ... = 6. Lấy 10 − 6 = 4. | T39: 85 | U39: =INDEX(Khung_cap_do!$H$2:$H$6,F39) | V39: 3 | W39: 10 | X39: T1.PT.06 | Y39: TOAN.SOTHIEU | Z39: Soạn thêm | AB39: Đã học cộng, trừ trong phạm vi 10. | AC39: Chương trình GDPT 2018 – Toán 1; đối chiếu SGK Kết nối tri thức. | AD39: EduChain Kids soạn thêm (2026-10); bám chương trình GDPT 2018 và trình tự SGK đã chọn | AE39: Bản soạn mới — cần rà soát | AF39: Chờ giáo viên duyệt
A40: EC1-069 | B40: Toán | C40: 1 | D40: Sau khi học cộng, trừ và so sánh số | E40: Tính rồi so sánh | F40: 5 | G40: Mở rộng | J40: Sắp xếp | K40: Xếp các phép tính theo kết quả từ bé đến lớn. (Các mục: 1 + 2 / 3 + 2 / 5 − 4 / 9 − 1) | Q40: 5 − 4 → 1 + 2 → 3 + 2 → 9 − 1 | R40: Kết quả lần lượt 1, 3, 5, 8. | S40: Tính trước: 5 − 4 = 1; 1 + 2 = 3; 3 + 2 = 5; 9 − 1 = 8. Xếp 1, 3, 5, 8. | T40: 90 | U40: =INDEX(Khung_cap_do!$H$2:$H$6,F40) | V40: 4 | W40: 9 | X40: T1.SO.02 | Y40: TOAN.SAPXEP | Z40: Soạn thêm | AB40: Đã học cộng, trừ, so sánh trong phạm vi 10. | AC40: Chương trình GDPT 2018 – Toán 1; đối chiếu SGK Kết nối tri thức. | AD40: EduChain Kids soạn thêm (2026-10); bám chương trình GDPT 2018 và trình tự SGK đã chọn | AE40: Bản soạn mới — cần rà soát | AF40: Chờ giáo viên duyệt
...

Sheet TiengViet_L1-L5
A1: ID | B1: Môn học | C1: Lớp | D1: Giai đoạn gợi ý | E1: Chủ đề / kỹ năng | F1: Cấp độ | G1: Tên cấp độ | H1: Cấp độ cũ (bộ mẫu) | I1: Lý do điều chỉnh cấp độ | J1: Loại câu hỏi | K1: Câu hỏi / nhiệm vụ | L1: Lựa chọn A | M1: Lựa chọn B | N1: Lựa chọn C | O1: Lựa chọn D | P1: Lựa chọn E | Q1: Đáp án đúng | R1: Lời giải / phản hồi | S1: Lời giải chi tiết | T1: Thời gian (giây) | U1: Điểm khi đúng | V1: Đề ôn | W1: Thứ tự trong đề | X1: Mã YCCĐ | Y1: Mã dạng bài | Z1: Nguồn câu | AA1: Bản dùng trong app (nếu khác câu gốc) | AB1: Điều kiện tiên quyết | AC1: Căn cứ chương trình / lưu ý đối chiếu | AD1: Nguồn / phạm vi | AE1: Trạng thái nội dung | AF1: Trạng thái giáo viên | AG1: Ghi chú kiểm duyệt
A2: EC1-016 | B2: Tiếng Việt | C2: 1 | D2: Sau khi học chữ tương ứng | E2: Nhận diện chữ | F2: 1 | G2: Làm quen | J2: Chọn đáp án | K2: Chọn chữ a. | L2: a | M2: o | N2: e | Q2: A | R2: Chữ cần tìm là a. | T2: 30 | U2: =INDEX(Khung_cap_do!$H$2:$H$6,F2) | V2: 1 | W2: 1 | X2: V1.AM.01 | Y2: TV.AMCHU | Z2: Bộ mẫu | AB2: Chữ a đã được dạy. | AC2: Gắn với tiến trình âm/chữ thực tế. | AD2: Chương trình GDPT 2018 / kế hoạch dạy học của trường; đối chiếu văn bản hiện hành | AE2: Bản mẫu — cần rà soát | AF2: Chờ giáo viên duyệt
A3: EC1-017 | B3: Tiếng Việt | C3: 1 | D3: Sau khi học chữ tương ứng | E3: Chữ đầu từ | F3: 1 | G3: Làm quen | J3: Chọn đáp án | K3: Từ nào bắt đầu bằng chữ b? | L3: bò | M3: cá | N3: gà | Q3: A | R3: “Bò” bắt đầu bằng chữ b. | T3: 30 | U3: =INDEX(Khung_cap_do!$H$2:$H$6,F3) | V3: 1 | W3: 2 | X3: V1.AM.01 | Y3: TV.AMCHU | Z3: Bộ mẫu | AB3: Chữ b và các từ lựa chọn đã được học. | AC3: Rà soát từ vựng theo SGK. | AD3: Chương trình GDPT 2018 / kế hoạch dạy học của trường; đối chiếu văn bản hiện hành | AE3: Bản mẫu — cần rà soát | AF3: Chờ giáo viên duyệt
A4: EC1-018 | B4: Tiếng Việt | C4: 1 | D4: Sau khi học dấu sắc | E4: Thanh điệu | F4: 1 | G4: Làm quen | J4: Chọn đáp án | K4: Chọn tiếng có dấu sắc. | L4: bé | M4: ba | N4: bà | Q4: A | R4: “Bé” mang dấu sắc. | T4: 30 | U4: =INDEX(Khung_cap_do!$H$2:$H$6,F4) | V4: 2 | W4: 1 | X4: V1.AM.02 | Y4: TV.DAUTHANH | Z4: Bộ mẫu | AB4: Đã học dấu sắc và các tiếng so sánh. | AC4: Chỉ dùng sau khi học dấu sắc. | AD4: Chương trình GDPT 2018 / kế hoạch dạy học của trường; đối chiếu văn bản hiện hành | AE4: Bản mẫu — cần rà soát | AF4: Chờ giáo viên duyệt
A5: EC1-071 | B5: Tiếng Việt | C5: 1 | D5: Sau khi học chữ m | E5: Nhận diện chữ | F5: 1 | G5: Làm quen | J5: Chọn đáp án | K5: Chọn chữ m. | L5: m | M5: n | N5: h | Q5: A | R5: Chữ cần tìm là m. | T5: 30 | U5: =INDEX(Khung_cap_do!$H$2:$H$6,F5) | V5: 2 | W5: 2 | X5: V1.AM.01 | Y5: TV.AMCHU | Z5: Soạn thêm | AB5: Đã học chữ m, n, h. | AC5: Chương trình GDPT 2018 – Tiếng Việt 1; đối chiếu SGK Kết nối tri thức (Tập 1). | AD5: EduChain Kids soạn thêm (2026-10); bám chương trình GDPT 2018 và trình tự SGK đã chọn | AE5: Bản soạn mới — cần rà soát | AF5: Chờ giáo viên duyệt
A6: EC1-072 | B6: Tiếng Việt | C6: 1 | D6: Sau khi học chữ c | E6: Chữ đầu tiếng | F6: 1 | G6: Làm quen | J6: Chọn đáp án | K6: Tiếng "cá" bắt đầu bằng chữ nào? | L6: c | M6: a | N6: k | Q6: A | R6: "Cá" gồm c và a, dấu sắc. | T6: 30 | U6: =INDEX(Khung_cap_do!$H$2:$H$6,F6) | V6: 3 | W6: 1 | X6: V1.AM.01 | Y6: TV.AMCHU | Z6: Soạn thêm | AB6: Đã học c, a và dấu sắc. | AC6: Chương trình GDPT 2018 – Tiếng Việt 1; đối chiếu SGK Kết nối tri thức (Tập 1). | AD6: EduChain Kids soạn thêm (2026-10); bám chương trình GDPT 2018 và trình tự SGK đã chọn | AE6: Bản soạn mới — cần rà soát | AF6: Chờ giáo viên duyệt
A7: EC1-073 | B7: Tiếng Việt | C7: 1 | D7: Sau khi học dấu huyền | E7: Thanh điệu | F7: 1 | G7: Làm quen | J7: Chọn đáp án | K7: Chọn tiếng có dấu huyền. | L7: bà | M7: bá | N7: bạ | Q7: A | R7: "Bà" mang dấu huyền. | T7: 30 | U7: =INDEX(Khung_cap_do!$H$2:$H$6,F7) | V7: 3 | W7: 2 | X7: V1.AM.02 | Y7: TV.DAUTHANH | Z7: Soạn thêm | AB7: Đã học dấu huyền, sắc, nặng. | AC7: Chương trình GDPT 2018 – Tiếng Việt 1; đối chiếu SGK Kết nối tri thức (Tập 1). | AD7: EduChain Kids soạn thêm (2026-10); bám chương trình GDPT 2018 và trình tự SGK đã chọn | AE7: Bản soạn mới — cần rà soát | AF7: Chờ giáo viên duyệt
A8: EC1-074 | B8: Tiếng Việt | C8: 1 | D8: Sau khi học dấu nặng | E8: Thanh điệu | F8: 1 | G8: Làm quen | J8: Đúng / Sai | K8: Tiếng "mẹ" có dấu nặng. | L8: Đúng | M8: Sai | Q8: A | R8: Dấu nặng đặt dưới chữ e trong "mẹ". | T8: 30 | U8: =INDEX(Khung_cap_do!$H$2:$H$6,F8) | V8: 4 | W8: 1 | X8: V1.AM.02 | Y8: TV.DAUTHANH | Z8: Soạn thêm | AB8: Đã học m, e và dấu nặng. | AC8: Chương trình GDPT 2018 – Tiếng Việt 1; đối chiếu SGK Kết nối tri thức (Tập 1). | AD8: EduChain Kids soạn thêm (2026-10); bám chương trình GDPT 2018 và trình tự SGK đã chọn | AE8: Bản soạn mới — cần rà soát | AF8: Chờ giáo viên duyệt
A9: EC1-075 | B9: Tiếng Việt | C9: 1 | D9: Sau khi học vần eo | E9: Nhận diện vần | F9: 1 | G9: Làm quen | J9: Chọn đáp án | K9: Tiếng "mèo" có vần gì? | L9: eo | M9: ao | N9: au | Q9: A | R9: "Mèo" = m + eo + dấu huyền. | T9: 30 | U9: =INDEX(Khung_cap_do!$H$2:$H$6,F9) | V9: 4 | W9: 2 | X9: V1.AM.03 | Y9: TV.GHEPVAN | Z9: Soạn thêm | AB9: Đã học vần ao, eo, au. | AC9: Chương trình GDPT 2018 – Tiếng Việt 1; đối chiếu SGK Kết nối tri thức (Tập 1). | AD9: EduChain Kids soạn thêm (2026-10); bám chương trình GDPT 2018 và trình tự SGK đã chọn | AE9: Bản soạn mới — cần rà soát | AF9: Chờ giáo viên duyệt
A10: EC1-019 | B10: Tiếng Việt | C10: 1 | D10: Sau khi học chữ để ghép tiếng | E10: Ghép tiếng | F10: 2 | G10: Cơ bản | J10: Chọn đáp án | K10: Chọn tiếng ghép được từ b và a. | L10: ba | M10: ca | N10: ma | Q10: A | R10: b ghép với a tạo thành “ba”. | T10: 40 | U10: =INDEX(Khung_cap_do!$H$2:$H$6,F10) | V10: 1 | W10: 3 | X10: V1.DOC.01 | Y10: TV.GHEPVAN | Z10: Bộ mẫu | AB10: Các chữ và thao tác ghép tiếng đã học. | AC10: Đối chiếu bài đã học. | AD10: Chương trình GDPT 2018 / kế hoạch dạy học của trường; đối chiếu văn bản hiện hành | AE10: Bản mẫu — cần rà soát | AF10: Chờ giáo viên duyệt
A11: EC1-020 | B11: Tiếng Việt | C11: 1 | D11: Sau khi học từ tương ứng | E11: Đọc từ | F11: 2 | G11: Cơ bản | J11: Chọn đáp án | K11: Từ nào chỉ một con vật? | L11: mèo | M11: bàn | N11: bút | Q11: A | R11: Mèo là tên một con vật. | T11: 40 | U11: =INDEX(Khung_cap_do!$H$2:$H$6,F11) | V11: 1 | W11: 4 | X11: V1.VIET.04 | Y11: TV.TUNGU | Z11: Bộ mẫu | AB11: Học sinh đọc được từ hoặc có hỗ trợ âm thanh. | AC11: Tránh kiểm tra vốn từ ngoài chương trình. | AD11: Chương trình GDPT 2018 / kế hoạch dạy học của trường; đối chiếu văn bản hiện hành | AE11: Bản mẫu — cần rà soát | AF11: Chờ giáo viên duyệt
A12: EC1-021 | B12: Tiếng Việt | C12: 1 | D12: Sau khi học câu ngắn | E12: Hiểu câu | F12: 2 | G12: Cơ bản | J12: Chọn đáp án | K12: Câu “Bé đá bóng.” nói về việc gì? | L12: Bé đá bóng | M12: Bé ngủ | N12: Bé ăn cơm | Q12: A | R12: Câu nêu việc bé đá bóng. | T12: 40 | U12: =INDEX(Khung_cap_do!$H$2:$H$6,F12) | V12: 2 | W12: 3 | X12: V1.DOC.04 | Y12: TV.DOCHIEU | Z12: Bộ mẫu | AA12: [Chọn đáp án] Câu "Bé đá bóng." nói về việc gì? A. Bé đá bóng | B. Bé ngủ | C. Bé ăn cơm Đáp án: A | AB12: Học sinh đọc/nghe được câu. | AC12: Câu ngắn, từ vựng quen thuộc. | AD12: Chương trình GDPT 2018 / kế hoạch dạy học của trường; đối chiếu văn bản hiện hành | AE12: Bản mẫu — cần rà soát | AF12: Chờ giáo viên duyệt
A13: EC1-024 | B13: Tiếng Việt | C13: 1 | D13: Sau khi học từ chỉ đặc điểm | E13: Từ ngữ | F13: 2 | G13: Cơ bản | H13: 3 | I13: Chỉ nhận biết nghĩa một từ quen thuộc, xếp L2. | J13: Chọn đáp án | K13: Chọn từ chỉ màu sắc. | L13: đỏ | M13: chạy | N13: ngủ | Q13: A | R13: “Đỏ” chỉ màu sắc. | T13: 40 | U13: =INDEX(Khung_cap_do!$H$2:$H$6,F13) | V13: 2 | W13: 4 | X13: V1.VIET.04 | Y13: TV.TUNGU | Z13: Bộ mẫu | AB13: Từ và khái niệm đã được giới thiệu. | AC13: Giáo viên xác nhận thuật ngữ phù hợp. | AD13: Chương trình GDPT 2018 / kế hoạch dạy học của trường; đối chiếu văn bản hiện hành | AE13: Bản mẫu — cần rà soát | AF13: Chờ giáo viên duyệt
A14: EC1-076 | B14: Tiếng Việt | C14: 1 | D14: Sau khi học quy tắc c/k | E14: Chính tả c/k | F14: 2 | G14: Cơ bản | J14: Điền đáp án | K14: Điền c hoặc k: cái ...ẹo | Q14: k | R14: Viết k trước e, ê, i: cái kẹo. | T14: 50 | U14: =INDEX(Khung_cap_do!$H$2:$H$6,F14) | V14: 3 | W14: 3 | X14: V1.AM.04 | Y14: TV.CHINHTA | Z14: Soạn thêm | AB14: Đã học c, k và quy tắc viết k trước e, ê, i. | AC14: Chương trình GDPT 2018 – Tiếng Việt 1; đối chiếu SGK Kết nối tri thức (Tập 1). | AD14: EduChain Kids soạn thêm (2026-10); bám chương trình GDPT 2018 và trình tự SGK đã chọn | AE14: Bản soạn mới — cần rà soát | AF14: Chờ giáo viên duyệt
A15: EC1-077 | B15: Tiếng Việt | C15: 1 | D15: Sau khi học các chữ c, g, b | E15: Đọc tiếng – nối tranh | F15: 2 | G15: Cơ bản | J15: Ghép cặp | K15: Nối tranh với tiếng. (Vế trái: 🐟 / 🐔 / 🐄 · Vế phải: bò / cá / gà) | Q15: 🐟 – cá; 🐔 – gà; 🐄 – bò | R15: 🐟 cá, 🐔 gà, 🐄 bò. | T15: 55 | U15: =INDEX(Khung_cap_do!$H$2:$H$6,F15) | V15: 3 | W15: 4 | X15: V1.DOC.05 | Y15: TV.NOITU | Z15: Soạn thêm | AB15: Đã đọc được cá, gà, bò. | AC15: Chương trình GDPT 2018 – Tiếng Việt 1; đối chiếu SGK Kết nối tri thức (Tập 1). | AD15: EduChain Kids soạn thêm (2026-10); bám chương trình GDPT 2018 và trình tự SGK đã chọn | AE15: Bản soạn mới — cần rà soát | AF15: Chờ giáo viên duyệt
A16: EC1-078 | B16: Tiếng Việt | C16: 1 | D16: Sau khi học vần ut, i | E16: Từ ngữ | F16: 2 | G16: Cơ bản | J16: Chọn đáp án | K16: Từ nào chỉ đồ dùng học tập? | L16: bút chì | M16: con cò | N16: quả na | Q16: A | R16: Bút chì là đồ dùng học tập. | T16: 40 | U16: =INDEX(Khung_cap_do!$H$2:$H$6,F16) | V16: 4 | W16: 3 | X16: V1.VIET.04 | Y16: TV.TUNGU | Z16: Soạn thêm | AB16: Đã đọc được bút chì, con cò, quả na. | AC16: Chương trình GDPT 2018 – Tiếng Việt 1; đối chiếu SGK Kết nối tri thức (Tập 1). | AD16: EduChain Kids soạn thêm (2026-10); bám chương trình GDPT 2018 và trình tự SGK đã chọn | AE16: Bản soạn mới — cần rà soát | AF16: Chờ giáo viên duyệt
A17: EC1-079 | B17: Tiếng Việt | C17: 1 | D17: Sau khi học chữ g | E17: Ghép tiếng | F17: 2 | G17: Cơ bản | J17: Điền đáp án | K17: g ghép với a, thêm dấu huyền, được tiếng gì? | Q17: gà | R17: g + a + dấu huyền = gà. | T17: 50 | U17: =INDEX(Khung_cap_do!$H$2:$H$6,F17) | V17: 4 | W17: 4 | X17: V1.DOC.01 | Y17: TV.GHEPVAN | Z17: Soạn thêm | AB17: Đã học g, a, dấu huyền. | AC17: Chương trình GDPT 2018 – Tiếng Việt 1; đối chiếu SGK Kết nối tri thức (Tập 1). | AD17: EduChain Kids soạn thêm (2026-10); bám chương trình GDPT 2018 và trình tự SGK đã chọn | AE17: Bản soạn mới — cần rà soát | AF17: Chờ giáo viên duyệt
A18: EC1-022 | B18: Tiếng Việt | C18: 1 | D18: Sau khi học các tiếng trong câu | E18: Sắp xếp tiếng | F18: 3 | G18: Vận dụng | J18: Sắp xếp | K18: Sắp xếp thành câu: “đọc / Lan / sách”. | Q18: Lan đọc sách. | R18: Sắp xếp thành câu có nghĩa. | S18: Câu cho biết ai (Lan) làm gì (đọc sách). Chữ đầu câu viết hoa: Lan đọc sách. | T18: 65 | U18: =INDEX(Khung_cap_do!$H$2:$H$6,F18) | V18: 1 | W18: 5 | X18: V1.VIET.03 | Y18: TV.XEPCAU | Z18: Bộ mẫu | AA18: [Sắp xếp] Sắp xếp thành câu: "đọc / Lan / sách". Đáp án: Lan → đọc → sách | AB18: Các tiếng đã học; đã làm quen câu đơn giản. | AC18: Đề xuất bài tập; giáo viên duyệt. | AD18: Chương trình GDPT 2018 / kế hoạch dạy học của trường; đối chiếu văn bản hiện hành | AE18: Bản mẫu — cần rà soát | AF18: Chờ giáo viên duyệt
A19: EC1-023 | B19: Tiếng Việt | C19: 1 | D19: Sau khi học câu ngắn | E19: Đọc hiểu | F19: 3 | G19: Vận dụng | J19: Chọn đáp án | K19: Đọc: “Nam tưới cây.” Ai tưới cây? | L19: Nam | M19: Cây | N19: Không rõ | Q19: A | R19: Câu cho biết Nam là người tưới cây. | S19: Hỏi "Ai?" là hỏi người làm việc. Trong câu, người tưới cây là Nam. | T19: 50 | U19: =INDEX(Khung_cap_do!$H$2:$H$6,F19) | V19: 1 | W19: 6 | X19: V1.DOC.04 | Y19: TV.DOCHIEU | Z19: Bộ mẫu | AA19: [Chọn đáp án] Đọc: "Nam tưới cây." Ai tưới cây? A. Nam | B. Cây | C. Không rõ Đáp án: A | AB19: Đọc được câu hoặc có audio hỗ trợ. | AC19: Tìm thông tin trực tiếp. | AD19: Chương trình GDPT 2018 / kế hoạch dạy học của trường; đối chiếu văn bản hiện hành | AE19: Bản mẫu — cần rà soát | AF19: Chờ giáo viên duyệt
A20: EC1-027 | B20: Tiếng Việt | C20: 1 | D20: Sau khi học các từ đã dùng | E20: Chọn từ | F20: 3 | G20: Vận dụng | H20: 4 | I20: Chọn một từ hợp nghĩa trong câu ngắn, xếp L3. | J20: Chọn đáp án | K20: Hoàn thành câu: “Bé ___ nước.” | L20: uống | M20: xanh | N20: bàn | Q20: A | R20: “Uống” phù hợp với “nước”. | S20: Nước là thứ để uống: "Bé uống nước." Hai từ còn lại không tạo thành câu có nghĩa. | T20: 50 | U20: =INDEX(Khung_cap_do!$H$2:$H$6,F20) | V20: 2 | W20: 5 | X20: V1.VIET.06 | Y20: TV.DOCHIEU | Z20: Bộ mẫu | AA20: [Chọn đáp án] Hoàn thành câu: "Bé ___ nước." A. uống | B. xanh | C. bàn Đáp án: A | AB20: Đọc hiểu nghĩa cơ bản của các từ. | AC20: Đề xuất nội bộ; không phải chuẩn chính thức. | AD20: Chương trình GDPT 2018 / kế hoạch dạy học của trường; đối chiếu văn bản hiện hành | AE20: Bản mẫu — cần rà soát | AF20: Chờ giáo viên duyệt
A21: EC1-080 | B21: Tiếng Việt | C21: 1 | D21: Sau khi học các tiếng trong câu | E21: Sắp xếp tiếng | F21: 3 | G21: Vận dụng | J21: Sắp xếp | K21: Xếp thành câu: "bé / Mẹ / ru". (Các mục: Mẹ / bé / ru) | Q21: Mẹ → ru → bé | R21: Mẹ ru bé. | S21: Ai? – Mẹ. Làm gì? – ru bé. Chữ đầu câu viết hoa: Mẹ ru bé. | T21: 65 | U21: =INDEX(Khung_cap_do!$H$2:$H$6,F21) | V21: 2 | W21: 6 | X21: V1.VIET.03 | Y21: TV.XEPCAU | Z21: Soạn thêm | AB21: Đã đọc được mẹ, ru, bé. | AC21: Chương trình GDPT 2018 – Tiếng Việt 1; đối chiếu SGK Kết nối tri thức (Tập 1). | AD21: EduChain Kids soạn thêm (2026-10); bám chương trình GDPT 2018 và trình tự SGK đã chọn | AE21: Bản soạn mới — cần rà soát | AF21: Chờ giáo viên duyệt
A22: EC1-081 | B22: Tiếng Việt | C22: 1 | D22: Sau khi học câu ngắn | E22: Đọc hiểu | F22: 3 | G22: Vận dụng | J22: Chọn đáp án | K22: Đọc: "Bố đi làm. Mẹ đi chợ." Ai đi chợ? | L22: Mẹ | M22: Bố | N22: Bé | Q22: A | R22: Câu thứ hai: Mẹ đi chợ. | S22: Đoạn có hai câu: Bố đi làm; Mẹ đi chợ. Người đi chợ là Mẹ. | T22: 50 | U22: =INDEX(Khung_cap_do!$H$2:$H$6,F22) | V22: 3 | W22: 5 | X22: V1.DOC.04 | Y22: TV.DOCHIEU | Z22: Soạn thêm | AB22: Đã đọc được câu ngắn có các tiếng này. | AC22: Chương trình GDPT 2018 – Tiếng Việt 1; đối chiếu SGK Kết nối tri thức (Tập 1). | AD22: EduChain Kids soạn thêm (2026-10); bám chương trình GDPT 2018 và trình tự SGK đã chọn | AE22: Bản soạn mới — cần rà soát | AF22: Chờ giáo viên duyệt
A23: EC1-082 | B23: Tiếng Việt | C23: 1 | D23: Sau khi học vần ong, am | E23: Từ ngữ | F23: 3 | G23: Vận dụng | J23: Chọn nhiều đáp án | K23: Chọn TẤT CẢ từ chỉ con vật. | L23: con gà | M23: cái ghế | N23: con thỏ | O23: quả cam | Q23: A, C | R23: Gà và thỏ là con vật. | S23: Con gà, con thỏ là con vật. Cái ghế là đồ vật, quả cam là quả. | T23: 60 | U23: =INDEX(Khung_cap_do!$H$2:$H$6,F23) | V23: 3 | W23: 6 | X23: V1.VIET.04 | Y23: TV.TUNGU | Z23: Soạn thêm | AB23: Đã đọc được các từ trong lựa chọn. | AC23: Chương trình GDPT 2018 – Tiếng Việt 1; đối chiếu SGK Kết nối tri thức (Tập 1). | AD23: EduChain Kids soạn thêm (2026-10); bám chương trình GDPT 2018 và trình tự SGK đã chọn | AE23: Bản soạn mới — cần rà soát | AF23: Chờ giáo viên duyệt
A24: EC1-083 | B24: Tiếng Việt | C24: 1 | D24: Sau khi học quy tắc g/gh | E24: Chính tả g/gh | F24: 3 | G24: Vận dụng | J24: Điền đáp án | K24: Điền g hoặc gh: cái ...ế | Q24: gh | R24: Viết gh trước e, ê, i: cái ghế. | S24: Sau chữ cần điền là ê. Trước e, ê, i ta viết gh: cái ghế. | T24: 60 | U24: =INDEX(Khung_cap_do!$H$2:$H$6,F24) | V24: 4 | W24: 5 | X24: V1.AM.04 | Y24: TV.CHINHTA | Z24: Soạn thêm | AB24: Đã học g, gh và quy tắc chính tả. | AC24: Chương trình GDPT 2018 – Tiếng Việt 1; đối chiếu SGK Kết nối tri thức (Tập 1). | AD24: EduChain Kids soạn thêm (2026-10); bám chương trình GDPT 2018 và trình tự SGK đã chọn | AE24: Bản soạn mới — cần rà soát | AF24: Chờ giáo viên duyệt
A25: EC1-084 | B25: Tiếng Việt | C25: 1 | D25: Sau khi học quy tắc ng/ngh | E25: Chính tả ng/ngh | F25: 3 | G25: Vận dụng | J25: Chọn đáp án | K25: Chọn từ viết đúng chính tả. | L25: nghỉ hè | M25: ngỉ hè | Q25: A | R25: Trước i viết ngh: nghỉ hè. | S25: Trước e, ê, i ta viết ngh. Vì vậy "nghỉ" viết ngh. | T25: 50 | U25: =INDEX(Khung_cap_do!$H$2:$H$6,F25) | V25: 4 | W25: 6 | X25: V1.AM.04 | Y25: TV.CHINHTA | Z25: Soạn thêm | AB25: Đã học ng, ngh và quy tắc chính tả. | AC25: Chương trình GDPT 2018 – Tiếng Việt 1; đối chiếu SGK Kết nối tri thức (Tập 1). | AD25: EduChain Kids soạn thêm (2026-10); bám chương trình GDPT 2018 và trình tự SGK đã chọn | AE25: Bản soạn mới — cần rà soát | AF25: Chờ giáo viên duyệt
A26: EC1-025 | B26: Tiếng Việt | C26: 1 | D26: Sau khi học dấu câu | E26: Dấu câu | F26: 4 | G26: Thử thách | J26: Chọn đáp án | K26: Chọn dấu cuối câu kể: “Em yêu trường em__” | L26: . | M26: ? | N26: , | Q26: A | R26: Câu kể thông thường kết thúc bằng dấu chấm. | S26: Câu này kể lại điều em nghĩ, không phải câu hỏi, nên cuối câu dùng dấu chấm. | T26: 60 | U26: =INDEX(Khung_cap_do!$H$2:$H$6,F26) | V26: 1 | W26: 7 | X26: V1.VIET.05 | Y26: TV.DAUCAU | Z26: Bộ mẫu | AA26: [Chọn đáp án] Chọn dấu cuối câu kể: "Em yêu trường em__" A. . | B. ? | C. , Đáp án: A | AB26: Dấu câu đã được dạy. | AC26: Xác nhận mốc dạy dấu câu. | AD26: Chương trình GDPT 2018 / kế hoạch dạy học của trường; đối chiếu văn bản hiện hành | AE26: Bản mẫu — cần rà soát | AF26: Chờ giáo viên duyệt
A27: EC1-026 | B27: Tiếng Việt | C27: 1 | D27: Sau khi học đọc câu ngắn | E27: Đọc hiểu | F27: 4 | G27: Thử thách | J27: Chọn đáp án | K27: Đọc: “Trời mưa. Hà mở ô.” Vì sao Hà mở ô? | L27: Vì trời mưa | M27: Vì trời nắng | N27: Vì Hà đi ngủ | Q27: A | R27: Hai câu gợi lý do Hà mở ô. | S27: Câu đầu cho biết trời mưa, câu sau Hà mở ô. Hà mở ô để che mưa. | T27: 60 | U27: =INDEX(Khung_cap_do!$H$2:$H$6,F27) | V27: 1 | W27: 8 | X27: V1.DOC.04 | Y27: TV.DOCHIEU | Z27: Bộ mẫu | AA27: [Chọn đáp án] Đọc: "Trời mưa. Hà mở ô." Vì sao Hà mở ô? A. Vì trời mưa | B. Vì trời nắng | C. Vì Hà đi ngủ Đáp án: A | AB27: Đọc được từ và câu trong đoạn. | AC27: Giáo viên rà soát vốn từ và vùng miền. | AD27: Chương trình GDPT 2018 / kế hoạch dạy học của trường; đối chiếu văn bản hiện hành | AE27: Bản mẫu — cần rà soát | AF27: Chờ giáo viên duyệt
